[2024-03-29T01:53:51.665+0000] {logging_mixin.py:151} INFO - Changing /opt/***/logs/dag_id=example_kubernetes_executor/run_id=manual__2024-03-29T01:53:37.362760+00:00/task_id=test_volume_mount permission to 509
[2024-03-29T01:53:51.666+0000] {logging_mixin.py:151} INFO - Failed to change /opt/***/logs/dag_id=example_kubernetes_executor/run_id=manual__2024-03-29T01:53:37.362760+00:00/task_id=test_volume_mount permission to 509: [Errno 1] Operation not permitted: '/opt/***/logs/dag_id=example_kubernetes_executor/run_id=manual__2024-03-29T01:53:37.362760+00:00/task_id=test_volume_mount'
[2024-03-29T01:53:51.698+0000] {logging_mixin.py:151} INFO - Changing /opt/***/logs/dag_id=example_kubernetes_executor/run_id=manual__2024-03-29T01:53:37.362760+00:00/task_id=test_volume_mount permission to 509
[2024-03-29T01:53:51.699+0000] {logging_mixin.py:151} INFO - Failed to change /opt/***/logs/dag_id=example_kubernetes_executor/run_id=manual__2024-03-29T01:53:37.362760+00:00/task_id=test_volume_mount permission to 509: [Errno 1] Operation not permitted: '/opt/***/logs/dag_id=example_kubernetes_executor/run_id=manual__2024-03-29T01:53:37.362760+00:00/task_id=test_volume_mount'
[2024-03-29T01:53:51.741+0000] {taskinstance.py:1157} INFO - Dependencies all met for dep_context=non-requeueable deps ti=<TaskInstance: example_kubernetes_executor.test_volume_mount manual__2024-03-29T01:53:37.362760+00:00 [queued]>
[2024-03-29T01:53:51.755+0000] {taskinstance.py:1157} INFO - Dependencies all met for dep_context=requeueable deps ti=<TaskInstance: example_kubernetes_executor.test_volume_mount manual__2024-03-29T01:53:37.362760+00:00 [queued]>
[2024-03-29T01:53:51.756+0000] {taskinstance.py:1359} INFO - Starting attempt 1 of 1
[2024-03-29T01:53:51.773+0000] {taskinstance.py:1380} INFO - Executing <Task(_PythonDecoratedOperator): test_volume_mount> on 2024-03-29 01:53:37.362760+00:00
[2024-03-29T01:53:51.782+0000] {standard_task_runner.py:57} INFO - Started process 107 to run task
[2024-03-29T01:53:51.786+0000] {standard_task_runner.py:84} INFO - Running: ['***', 'tasks', 'run', 'example_kubernetes_executor', 'test_volume_mount', 'manual__2024-03-29T01:53:37.362760+00:00', '--job-id', '7', '--raw', '--subdir', '/home/***/.local/lib/python3.8/site-packages/***/example_dags/example_kubernetes_executor.py', '--cfg-path', '/tmp/tmp9pmot5_f']
[2024-03-29T01:53:51.790+0000] {standard_task_runner.py:85} INFO - Job 7: Subtask test_volume_mount
[2024-03-29T01:53:51.852+0000] {logging_mixin.py:151} INFO - Changing /opt/***/logs/dag_id=example_kubernetes_executor/run_id=manual__2024-03-29T01:53:37.362760+00:00/task_id=test_volume_mount permission to 509
[2024-03-29T01:53:51.853+0000] {logging_mixin.py:151} INFO - Failed to change /opt/***/logs/dag_id=example_kubernetes_executor/run_id=manual__2024-03-29T01:53:37.362760+00:00/task_id=test_volume_mount permission to 509: [Errno 1] Operation not permitted: '/opt/***/logs/dag_id=example_kubernetes_executor/run_id=manual__2024-03-29T01:53:37.362760+00:00/task_id=test_volume_mount'
[2024-03-29T01:53:51.856+0000] {task_command.py:415} INFO - Running <TaskInstance: example_kubernetes_executor.test_volume_mount manual__2024-03-29T01:53:37.362760+00:00 [running]> on host 1279dfb12ee8
[2024-03-29T01:53:51.961+0000] {taskinstance.py:1660} INFO - Exporting env vars: AIRFLOW_CTX_DAG_OWNER='***' AIRFLOW_CTX_DAG_ID='example_kubernetes_executor' AIRFLOW_CTX_TASK_ID='test_volume_mount' AIRFLOW_CTX_EXECUTION_DATE='2024-03-29T01:53:37.362760+00:00' AIRFLOW_CTX_TRY_NUMBER='1' AIRFLOW_CTX_DAG_RUN_ID='manual__2024-03-29T01:53:37.362760+00:00'
[2024-03-29T01:53:51.989+0000] {taskinstance.py:1935} ERROR - Task failed with exception
Traceback (most recent call last):
  File "/home/airflow/.local/lib/python3.8/site-packages/airflow/decorators/base.py", line 221, in execute
    return_value = super().execute(context)
  File "/home/airflow/.local/lib/python3.8/site-packages/airflow/operators/python.py", line 192, in execute
    return_value = self.execute_callable()
  File "/home/airflow/.local/lib/python3.8/site-packages/airflow/operators/python.py", line 209, in execute_callable
    return self.python_callable(*self.op_args, **self.op_kwargs)
  File "/home/airflow/.local/lib/python3.8/site-packages/airflow/example_dags/example_kubernetes_executor.py", line 90, in test_volume_mount
    with open("/foo/volume_mount_test.txt", "w") as foo:
FileNotFoundError: [Errno 2] No such file or directory: '/foo/volume_mount_test.txt'
[2024-03-29T01:53:52.013+0000] {taskinstance.py:1398} INFO - Marking task as FAILED. dag_id=example_kubernetes_executor, task_id=test_volume_mount, execution_date=20240329T015337, start_date=20240329T015351, end_date=20240329T015352
[2024-03-29T01:53:52.033+0000] {standard_task_runner.py:104} ERROR - Failed to execute job 7 for task test_volume_mount ([Errno 2] No such file or directory: '/foo/volume_mount_test.txt'; 107)
[2024-03-29T01:53:52.079+0000] {local_task_job_runner.py:228} INFO - Task exited with return code 1
[2024-03-29T01:53:52.134+0000] {taskinstance.py:2776} INFO - 0 downstream tasks scheduled from follow-on schedule check
